<?xml version="1.0" ?>
<robot name="hand">
  <link name="panda_hand">
    <visual>
      <geometry>
        <mesh filename="package://urdf_rviz_display/gsmini_panda_hand/meshes/visual/hand.dae"/>
      </geometry>
    </visual>
    <collision>
      <geometry>
        <mesh filename="package://urdf_rviz_display/gsmini_panda_hand/meshes/collision/hand.stl"/>
      </geometry>
    </collision>
    <inertial>
      <origin rpy="0 0 0" xyz="0 0.0015244 0.0275912"/>
      <mass value="0.73"/>
      <inertia ixx="0.00278560230025" ixy="0.0" ixz="0.0" iyy="0.000400033405336" iyz="0.0" izz="0.00256378041832"/>
    </inertial>
  </link>
  <link name="panda_left_adapt_finger">
    <visual>
      <origin rpy="-1.570796327 0 0" xyz="-0.015 0 0"/>
      <geometry>
        <mesh filename="package://urdf_rviz_display/gsmini_panda_hand/meshes/collision/finger_gsmini_adapter.stl"/>
      </geometry>
    </visual>
    <collision>
      <origin rpy="-1.570796327 0 0" xyz="-0.015 0 0"/>
      <geometry>
        <mesh filename="package://urdf_rviz_display/gsmini_panda_hand/meshes/collision/finger_gsmini_adapter.stl"/>
      </geometry>
    </collision>
  </link>
  <link name="panda_right_adapt_finger">
    <visual>
      <origin rpy="-1.570796327 0 3.141592653589793" xyz="0.015 0 0"/>
      <geometry>
        <mesh filename="package://urdf_rviz_display/gsmini_panda_hand/meshes/collision/finger_gsmini_adapter.stl"/>
      </geometry>
    </visual>
    <collision>
      <origin rpy="-1.570796327 0 3.141592653589793" xyz="0.015 0 0"/>
      <geometry>
        <mesh filename="package://urdf_rviz_display/gsmini_panda_hand/meshes/collision/finger_gsmini_adapter.stl"/>
                               src/urdf_rviz_display/gsmini_panda_hand/urdf/hand_gsmini.urdf
      </geometry>
    </collision>
  </link>
  <link concave="yes" name="gsmini_left">
    <visual>
      <origin rpy="-1.570796327 -1.570796327 0" xyz="0 0 0"/>
      <geometry>
        <mesh filename="package://urdf_rviz_display/gsmini_panda_hand/meshes/collision/gsmini.stl"/>
      </geometry>
    </visual>
    <collision concave="yes">
      <origin rpy="-1.570796327 -1.570796327 0" xyz="0 0 0"/>
      <geometry>
        <mesh filename="package://urdf_rviz_display/gsmini_panda_hand/meshes/collision/gsmini.stl"/>
      </geometry>
    </collision>
  </link>
  <link concave="yes" name="gsmini_right">
    <visual>
      <origin rpy="1.570796327 1.570796327 0" xyz="0 0 0"/>
      <geometry>
        <mesh filename="package://urdf_rviz_display/gsmini_panda_hand/meshes/collision/gsmini.stl"/>
      </geometry>
    </visual>
    <collision concave="yes">
      <origin rpy="1.570796327 1.570796327 0" xyz="0 0 0"/>
      <geometry>
        <mesh filename="package://urdf_rviz_display/gsmini_panda_hand/meshes/collision/gsmini.stl"/>
      </geometry>
    </collision>
  </link>
  
  <joint name="panda_finger_joint_left" type="prismatic">
    <parent link="panda_hand"/>
    <child link="panda_left_adapt_finger"/>
    <!-- <origin rpy="0 0 0" xyz="-0.0149 (0.0064 - 0.0063) (0.0962 + 0.0584)"/> -->
    <origin rpy="0 0 0" xyz="0 0.04 0.1546"/>
    <axis xyz="0 -1 0"/>
    <limit effort="70" lower="0.0" upper="0.04" velocity="0.2"/>
    <dynamics damping="500.0" friction="100"/>
  </joint>
  <joint name="panda_finger_joint_right" type="prismatic">
    <parent link="panda_hand"/>
    <child link="panda_right_adapt_finger"/>
    <origin rpy="0 0 0" xyz="0 -0.04 0.1546"/>
    <axis xyz="0 1 0"/>
    <limit effort="70" lower="0.0" upper="0.04" velocity="0.2"/>
    <dynamics damping="500.0" friction="100"/>
    <!-- <mimic joint="panda_finger_joint_left"/> -->
  </joint>
  <joint name="finger_gsmini_joint_left" type="fixed">
    <parent link="panda_left_adapt_finger"/>
    <child link="gsmini_left"/>
    <origin rpy="0 0 -1.570796327" xyz="0 0.02315 -0.01675"/>
  </joint>
  <joint name="finger_gsmini_joint_right" type="fixed">
    <parent link="panda_right_adapt_finger"/>
    <child link="gsmini_right"/>
    <origin rpy="0 0 1.570796327" xyz="0 -0.02315 -0.01675"/>
  </joint>
</robot>
