<?xml version="1.0" ?>
<robot name="hand">
  <link name="dummylink">
    <visual>
      <geometry>
          <cylinder length="0.01" radius="0.005"/> 
      </geometry>
    </visual>
  </link>

  <link name="panda_hand">
    <visual>
      <geometry>
        <mesh filename="../meshes/visual/hand.dae"/>
      </geometry>
    </visual>
    <collision>
      <geometry>
        <mesh filename="../meshes/collision/hand.stl"/>
      </geometry>
    </collision>
  </link>
  <link name="panda_left_adapt_finger">
    <visual>
      <origin rpy="-1.570796327 0 0" xyz="-0.015 0 0"/>
      <geometry>
        <mesh filename="../meshes/collision/finger_gsmini_adapter.stl"/>
      </geometry>
    </visual>
    <collision>
      <origin rpy="-1.570796327 0 0" xyz="-0.015 0 0"/>
      <geometry>
        <mesh filename="../meshes/collision/finger_gsmini_adapter.stl"/>
      </geometry>
    </collision>
  </link>
  <link name="panda_right_adapt_finger">
    <visual>
      <origin rpy="-1.570796327 0 3.141592653589793" xyz="0.015 0 0"/>
      <geometry>
        <mesh filename="../meshes/collision/finger_gsmini_adapter.stl"/>
      </geometry>
    </visual>
    <collision>
      <origin rpy="-1.570796327 0 3.141592653589793" xyz="0.015 0 0"/>
      <geometry>
        <mesh filename="../meshes/collision/finger_gsmini_adapter.stl"/>
      </geometry>
    </collision>
  </link>
  <link name="gsmini_left">
    <visual>
      <origin rpy="-1.570796327 -1.570796327 0" xyz="0 0 0"/>
      <geometry>
        <mesh filename="../meshes/collision/gsmini.stl"/>
      </geometry>
    </visual>
    <collision>
      <origin rpy="-1.570796327 -1.570796327 0" xyz="0 0 0"/>
      <geometry>
        <mesh filename="../meshes/collision/gsmini.stl"/>
      </geometry>
    </collision>
  </link>
  <link name="gsmini_right">
    <visual>
      <origin rpy="1.570796327 1.570796327 0" xyz="0 0 0"/>
      <geometry>
        <mesh filename="../meshes/collision/gsmini.stl"/>
      </geometry>
    </visual>
    <collision >
      <origin rpy="1.570796327 1.570796327 0" xyz="0 0 0"/>
      <geometry>
        <mesh filename="../meshes/collision/gsmini.stl"/>
      </geometry>
    </collision>
  </link>

  <joint name="dummyjoint" type="prismatic">
    <parent link="dummylink"/>
    <child link="panda_hand"/>
    <origin xyz="0 0 0" rpy="0 0 0"/>
    <axis xyz="0 1 0"/> 
    <limit lower="-0.0001" upper="0.0001" effort="100" velocity="0.001"/> 
  </joint>  

  <joint name="panda_finger_joint_left" type="prismatic">
    <parent link="panda_hand"/>
    <child link="panda_left_adapt_finger"/>
    <origin rpy="0 0 0" xyz="0 0.04 0.1546"/>
    <axis xyz="0 -1 0"/>
    <limit effort="100" lower="0.0" upper="0.04" velocity="0.2"/>
    <dynamics damping="500.0" friction="100"/>
  </joint>
  <joint name="panda_finger_joint_right" type="prismatic">
    <parent link="panda_hand"/>
    <child link="panda_right_adapt_finger"/>
    <origin rpy="0 0 0" xyz="0 -0.04 0.1546"/>
    <axis xyz="0 1 0"/>
    <limit effort="100" lower="0.0" upper="0.04" velocity="0.2"/>
    <dynamics damping="500.0" friction="100"/>
    <!-- <mimic joint="panda_finger_joint_left"/> -->
  </joint>
  <joint name="finger_gsmini_joint_left" type="fixed">
    <parent link="panda_left_adapt_finger"/>
    <child link="gsmini_left"/>
    <origin rpy="0 0 -1.570796327" xyz="0 0.02315 -0.01675"/>
  </joint>
  <joint name="finger_gsmini_joint_right" type="fixed">
    <parent link="panda_right_adapt_finger"/>
    <child link="gsmini_right"/>
    <origin rpy="0 0 1.570796327" xyz="0 -0.02315 -0.01675"/>
  </joint>

</robot>
