<?xml version="1.0" ?>
<robot name="hand">
  <link name="panda_hand">
    <visual>
      <geometry>
        <mesh filename="package://urdf_rviz_display/franka_panda_description/meshes/visual/hand.dae"/>
      </geometry>
    </visual>
    <collision>
      <geometry>
        <mesh filename="package://urdf_rviz_display/franka_panda_description/meshes/collision/hand.stl"/>
      </geometry>
    </collision>
    <inertial>
      <origin rpy="0 0 0" xyz="0 0.0015244 0.0275912"/>
      <mass value="0.73"/>
      <inertia ixx="0.00278560230025" ixy="0.0" ixz="0.0" iyy="0.000400033405336" iyz="0.0" izz="0.00256378041832"/>
    </inertial>
  </link>
  <link name="panda_left_adapt_finger">
    <visual>
      <!-- some adjustment on origin coor -->
      <!-- <origin rpy="0 0 0" xyz="0 0 0"/> -->
      <origin rpy="-1.570796327 0 0" xyz="0 0 0"/>
      <geometry>
        <mesh filename="package://urdf_rviz_display/franka_panda_description/meshes/visual/finger_gsmini_adapter.dae"/>
      </geometry>
    </visual>
    <collision>
      <!-- <origin rpy="0 0 0" xyz="0 0 0"/> -->
      <origin rpy="-1.570796327 0 0" xyz="0 0 0"/>
      <geometry>
        <mesh filename="package://urdf_rviz_display/franka_panda_description/meshes/collision/finger_gsmini_adapter.stl"/>
      </geometry>
    </collision>
    <!-- no more inertial info -->
  </link>
  <link name="panda_right_adapt_finger">
    <visual>
      <!-- <origin rpy="0 0 3.141592653589793" xyz="0 0 0"/> -->
      <origin rpy="-1.570796327 0 3.141592653589793" xyz="0 0 0"/>
      <geometry>
        <mesh filename="package://urdf_rviz_display/franka_panda_description/meshes/visual/finger_gsmini_adapter.dae"/>
      </geometry>
    </visual>
    <collision>
      <!-- <origin rpy="0 0 3.141592653589793" xyz="0 0 0"/> -->
      <origin rpy="-1.570796327 0 3.141592653589793" xyz="0 0 0"/>
      <geometry>
        <mesh filename="package://urdf_rviz_display/franka_panda_description/meshes/collision/finger_gsmini_adapter.stl"/>
      </geometry>
    </collision>
    <!-- no more inertial info -->
  </link>
  <link name="gsmini_left">
    <visual>
      <origin rpy="-1.570796327 -1.570796327 0" xyz="0 0 0"/>
      <geometry>
        <mesh filename="package://urdf_rviz_display/franka_panda_description/meshes/visual/gsmini.dae"/>
      </geometry>
    </visual>
    <collision>
      <origin rpy="-1.570796327 -1.570796327 0" xyz="0 0 0"/>
      <geometry>
        <mesh filename="package://urdf_rviz_display/franka_panda_description/meshes/collision/gsmini.stl"/>
      </geometry>
    </collision>
  </link>
  <link name="gsmini_right">
    <visual>
      <origin rpy="1.570796327 1.570796327 0" xyz="0 0 0"/>
      <geometry>
        <mesh filename="package://urdf_rviz_display/franka_panda_description/meshes/visual/gsmini.dae"/>
      </geometry>
    </visual>
    <collision>
      <origin rpy="1.570796327 1.570796327 0" xyz="0 0 0"/>
      <geometry>
        <mesh filename="package://urdf_rviz_display/franka_panda_description/meshes/collision/gsmini.stl"/>
      </geometry>
    </collision>
  </link>
  
  <joint name="panda_finger_joint_left" type="prismatic">
    <parent link="panda_hand"/>
    <child link="panda_left_adapt_finger"/>
    <!-- some adjustment -->
    <!-- old <origin rpy="0 0 0" xyz="0 0 0.0584"/> -->
    <!-- new origin xyz = "0 (0 + 0.0114) (0.0584 + 0.0186) " -->
    <origin rpy="0 0 0" xyz="0 0.0114 0.0770"/>
    <axis xyz="0 1 0"/>
    <limit effort="20" lower="0.0" upper="0.04" velocity="0.2"/>
    <dynamics damping="500.0" friction="0.0"/>
  </joint>
  <joint name="panda_finger_joint_right" type="prismatic">
    <parent link="panda_hand"/>
    <child link="panda_right_adapt_finger"/>
    <!-- old <origin rpy="0 0 0" xyz="0 0 0.0584"/> -->
    <!-- new <origin xyz="0 (0 - 0.0114) (0.0584 + 0.0186)"/> -->
    <origin rpy="0 0 0" xyz="0 -0.0114 0.0770"/>
    <axis xyz="0 -1 0"/>
    <limit effort="20" lower="0.0" upper="0.04" velocity="0.2"/>
    <dynamics damping="500.0" friction="0.0"/>
    <mimic joint="panda_finger_joint_left"/>
  </joint>
  <joint name="finger_gsmini_joint_left" type="fixed">
    <parent link="panda_left_adapt_finger"/>
    <child link="gsmini_left"/>
    <origin rpy="0 0 -1.570796327" xyz="0 0.0120 0.0600"/>
  </joint>
  <joint name="finger_gsmini_joint_right" type="fixed">
    <parent link="panda_right_adapt_finger"/>
    <child link="gsmini_right"/>
    <origin rpy="0 0 1.570796327" xyz="0 -0.0120 0.0600"/>
  </joint>
</robot>
